2024-06-27 14:31:52 ERROR 400 response executing GraphQL.
2024-06-27 14:31:52 ERROR {"errors":[{"message":"Sweep l2p_bp/frequency_prompt_tuning/1bgsjmwk is not running","path":["createAgent"]}],"data":{"createAgent":null}}
2024-06-27 14:31:52 ERROR Traceback (most recent call last):
  File "/data1/deepdog/anaconda3/envs/l2p/lib/python3.9/site-packages/wandb/sdk/lib/retry.py", line 131, in __call__
    result = self._call_fn(*args, **kwargs)
  File "/data1/deepdog/anaconda3/envs/l2p/lib/python3.9/site-packages/wandb/sdk/internal/internal_api.py", line 340, in execute
    return self.client.execute(*args, **kwargs)  # type: ignore
  File "/data1/deepdog/anaconda3/envs/l2p/lib/python3.9/site-packages/wandb/vendor/gql-0.2.0/wandb_gql/client.py", line 52, in execute
    result = self._get_result(document, *args, **kwargs)
  File "/data1/deepdog/anaconda3/envs/l2p/lib/python3.9/site-packages/wandb/vendor/gql-0.2.0/wandb_gql/client.py", line 60, in _get_result
    return self.transport.execute(document, *args, **kwargs)
  File "/data1/deepdog/anaconda3/envs/l2p/lib/python3.9/site-packages/wandb/sdk/lib/gql_request.py", line 59, in execute
    request.raise_for_status()
  File "/data1/deepdog/anaconda3/envs/l2p/lib/python3.9/site-packages/requests/models.py", line 1024, in raise_for_status
    raise HTTPError(http_error_msg, response=self)
requests.exceptions.HTTPError: 400 Client Error: Bad Request for url: https://api.wandb.ai/graphql

During handling of the above exception, another exception occurred:

Traceback (most recent call last):
  File "/data1/deepdog/anaconda3/envs/l2p/lib/python3.9/site-packages/wandb/cli/cli.py", line 108, in wrapper
    return func(*args, **kwargs)
  File "/data1/deepdog/anaconda3/envs/l2p/lib/python3.9/site-packages/wandb/cli/cli.py", line 1807, in agent
    wandb_agent.agent(sweep_id, entity=entity, project=project, count=count)
  File "/data1/deepdog/anaconda3/envs/l2p/lib/python3.9/site-packages/wandb/wandb_agent.py", line 570, in agent
    return run_agent(
  File "/data1/deepdog/anaconda3/envs/l2p/lib/python3.9/site-packages/wandb/wandb_agent.py", line 528, in run_agent
    agent.run()
  File "/data1/deepdog/anaconda3/envs/l2p/lib/python3.9/site-packages/wandb/wandb_agent.py", line 201, in run
    agent = self._api.register_agent(socket.gethostname(), sweep_id=self._sweep_id)
  File "/data1/deepdog/anaconda3/envs/l2p/lib/python3.9/site-packages/wandb/apis/internal.py", line 150, in register_agent
    return self.api.register_agent(*args, **kwargs)
  File "/data1/deepdog/anaconda3/envs/l2p/lib/python3.9/site-packages/wandb/apis/normalize.py", line 73, in wrapper
    raise err
  File "/data1/deepdog/anaconda3/envs/l2p/lib/python3.9/site-packages/wandb/apis/normalize.py", line 41, in wrapper
    return func(*args, **kwargs)
  File "/data1/deepdog/anaconda3/envs/l2p/lib/python3.9/site-packages/wandb/sdk/internal/internal_api.py", line 2810, in register_agent
    response = self.gql(
  File "/data1/deepdog/anaconda3/envs/l2p/lib/python3.9/site-packages/wandb/sdk/internal/internal_api.py", line 312, in gql
    ret = self._retry_gql(
  File "/data1/deepdog/anaconda3/envs/l2p/lib/python3.9/site-packages/wandb/sdk/lib/retry.py", line 147, in __call__
    retry_timedelta_triggered = check_retry_fn(e)
  File "/data1/deepdog/anaconda3/envs/l2p/lib/python3.9/site-packages/wandb/util.py", line 878, in no_retry_4xx
    raise UsageError(body["errors"][0]["message"])
wandb.errors.UsageError: Sweep l2p_bp/frequency_prompt_tuning/1bgsjmwk is not running

